Traceback (most recent call last):
  File "/home/hoaf13/workspace/web_app/django/smartcall_map_location_django/venv/lib/python3.9/site-packages/environ/environ.py", line 367, in get_value
    value = self.ENVIRON[var]
  File "/usr/lib/python3.9/os.py", line 679, in __getitem__
    raise KeyError(key) from None
KeyError: 'DATABASE_PORT'

During handling of the above exception, another exception occurred:

Traceback (most recent call last):
  File "/home/hoaf13/workspace/web_app/django/smartcall_map_location_django/manage.py", line 22, in <module>
    main()
  File "/home/hoaf13/workspace/web_app/django/smartcall_map_location_django/manage.py", line 18, in main
    execute_from_command_line(sys.argv)
  File "/home/hoaf13/workspace/web_app/django/smartcall_map_location_django/venv/lib/python3.9/site-packages/django/core/management/__init__.py", line 446, in execute_from_command_line
    utility.execute()
  File "/home/hoaf13/workspace/web_app/django/smartcall_map_location_django/venv/lib/python3.9/site-packages/django/core/management/__init__.py", line 440, in execute
    self.fetch_command(subcommand).run_from_argv(self.argv)
  File "/home/hoaf13/workspace/web_app/django/smartcall_map_location_django/venv/lib/python3.9/site-packages/django/core/management/base.py", line 414, in run_from_argv
    self.execute(*args, **cmd_options)
  File "/home/hoaf13/workspace/web_app/django/smartcall_map_location_django/venv/lib/python3.9/site-packages/django/core/management/commands/runserver.py", line 74, in execute
    super().execute(*args, **options)
  File "/home/hoaf13/workspace/web_app/django/smartcall_map_location_django/venv/lib/python3.9/site-packages/django/core/management/base.py", line 460, in execute
    output = self.handle(*args, **options)
  File "/home/hoaf13/workspace/web_app/django/smartcall_map_location_django/venv/lib/python3.9/site-packages/django/core/management/commands/runserver.py", line 81, in handle
    if not settings.DEBUG and not settings.ALLOWED_HOSTS:
  File "/home/hoaf13/workspace/web_app/django/smartcall_map_location_django/venv/lib/python3.9/site-packages/django/conf/__init__.py", line 87, in __getattr__
    self._setup(name)
  File "/home/hoaf13/workspace/web_app/django/smartcall_map_location_django/venv/lib/python3.9/site-packages/django/conf/__init__.py", line 74, in _setup
    self._wrapped = Settings(settings_module)
  File "/home/hoaf13/workspace/web_app/django/smartcall_map_location_django/venv/lib/python3.9/site-packages/django/conf/__init__.py", line 183, in __init__
    mod = importlib.import_module(self.SETTINGS_MODULE)
  File "/usr/lib/python3.9/importlib/__init__.py", line 127, in import_module
    return _bootstrap._gcd_import(name[level:], package, level)
  File "<frozen importlib._bootstrap>", line 1030, in _gcd_import
  File "<frozen importlib._bootstrap>", line 1007, in _find_and_load
  File "<frozen importlib._bootstrap>", line 986, in _find_and_load_unlocked
  File "<frozen importlib._bootstrap>", line 680, in _load_unlocked
  File "<frozen importlib._bootstrap_external>", line 855, in exec_module
  File "<frozen importlib._bootstrap>", line 228, in _call_with_frames_removed
  File "/home/hoaf13/workspace/web_app/django/smartcall_map_location_django/smartcall_map_location_django/settings.py", line 88, in <module>
    'PORT': env('DATABASE_PORT'),
  File "/home/hoaf13/workspace/web_app/django/smartcall_map_location_django/venv/lib/python3.9/site-packages/environ/environ.py", line 175, in __call__
    return self.get_value(
  File "/home/hoaf13/workspace/web_app/django/smartcall_map_location_django/venv/lib/python3.9/site-packages/environ/environ.py", line 371, in get_value
    raise ImproperlyConfigured(error_msg)
django.core.exceptions.ImproperlyConfigured: Set the DATABASE_PORT environment variable
